Workbook
Name CONTRATTO: Elenchi!$A$36:$A$52
Name DESTINAZIONE_CDC: Elenchi!$L$5:$L$228
Name DESTINAZIONE_SOCIETA: Elenchi!$D$5:$D$21
Name DESTINAZIONE_VIA: Elenchi!$G$5:$G$29
Name EMAIL: Elenchi!$A$19:$A$20
Name MANSIONE: Elenchi!$A$84:$A$112
Name MOVIMENTO: Elenchi!$A$5:$A$15
Name ONBOARDING: Elenchi!$A$131:$A$133
Name PROVENIENZA_CDC: Elenchi!$AB$5:$AB$228
Name PROVENIENZA_SOCIETA: Elenchi!$T$5:$T$19
Name PROVENIENZA_VIA: Elenchi!$W$5:$W$27
Name QUALIFICA: Elenchi!$A$56:$A$69
Name SESSO: Elenchi!$A$29:$A$32
Name STATO: Elenchi!$A$73:$A$80
Name TELELAVORO: Elenchi!$A$24:$A$25

Sheet Scheda Movimento
A1: Scheda movimenti PERSONALE
A3: =IF(B3="","","Oggetto e-mail: ") -> Oggetto e-mail: | B3: =IF(C6="","",CONCATENATE("Comunic. ",C6,": ",C7," ",C8," - ",C22," - ",C20," - ",TEXT(C5,"gg.mm.aa"))) -> Comunic. INGRESSO: IACOVELLI ALESSANDRA - DIRIGENTE - MILANO - 16.03.26
A4: Voci movimento | B4: Cod. | C4: Descrizione movimento | D4: Con Elenco
A5: Decorrenza [data] | C5: 46097
A6: Movimento | C6: INGRESSO | D6: ▼
A7: Cognome | C7: IACOVELLI
A8: Nome | C8: ALESSANDRA
A9: Sesso | B9: =Elenchi!B27 -> F | C9: Femminile | D9: ▼
A10: Codice Fiscale | C10: CVLLSN80R49D643R
A11: Data di nascita | C11: 29503
A12: Comune di nascita | C12: FOGGIA
A13: Provincia di nascita | C13: FOGGIA
A14: Nazione di nascita | C14: ITALIA
A15: Società | B15: =IF(C15="","",Elenchi!E3) -> 15 | C15: IL SOLE 24 ORE S.P.A. | D15: ▼
A16: Area | C16: =IF(B18="","",Elenchi!Q3) -> DG I&S - DIR INFORMATION TECHNOLOGY
A17: Sotto Area | C17: =IF(B18="","",Elenchi!O3) -> DIR INFORMATION TECHNOLOGY
A18: Centro di Costo | B18: 415300 | C18: =IF(B18="","",Elenchi!M3) -> DIR INFORMATION TECHNOLOGY | D18: ▼
A19: Indirizzo sede | C19: VIALE SARCA 223 - MILANO (MI) | D19: ▼
A20: Cod. e Città sede | B20: =IF(C19="","",Elenchi!J3) -> 34 | C20: =IF(C19="","",Elenchi!H3) -> MILANO
A21: Contratto (Sicurezza Lavoro*) | B21: =IF(C21="","",Elenchi!B34) -> 02 | C21: Contratto a tempo indeterminato | D21: ▼
A22: Qualifica | B22: =IF(C22="","",Elenchi!B54) -> D | C22: DIRIGENTE | D22: ▼
A23: Codice Oneservice | B23: =IF(C23="","",C23) -> 3176 | C23: 3176
A24: Telelavoro | C24: NO | D24: ▼
A25: E-mail prefisso "EXT" | C25: No | D25: ▼
A26: E-mail suffisso (proposta) | C26: @ilsole24ore.com | D26: ▼
A27: E-mail (proposta) | C27: =IF(C7="","",CONCATENATE(_xlfn.TEXTBEFORE(CONCATENATE(LOWER(REPLACE(C8,1,,""))," ")," "),".",LOWER(REPLACE(C7,1,,"")),C26)) -> alessandra.iacovelli@ilsole24ore.com
A28: Stato (Serv, Mat.; Asp; Usc) | B28: =IF(C28="","",Elenchi!B71) -> S | C28: Servizio (in) | D28: ▼
A29: Data scadenza
A30: Job Title/Mansione
A31: Mansione (Sicurezza Lavoro*) | B31: =IF(C31="","",Elenchi!B82) -> IMP_VDT | C31: IMPIEGATO CON USO VDT | D31: ▼
A32: Formazione Salute e Sicurezza Lav. | C32: =IF(C6="INGRESSO",IF(C21="","",IF(C21="Contratto a Part. IVA","NO","SI")),"") -> SI
A33: Referente diretto | C33: Boromei Paola
A34: Provenienza Società (distacco e trasfer.to) | B34: =IF(C34="","",Elenchi!U3) | D34: ▼
A35: Area | B35: =IF(C35="","",Elenchi!AF3) | C35: =IF(B37="","",Elenchi!AG3)
A36: Sotto Area | B36: =IF(C36="","",Elenchi!AD3) | C36: =IF(B37="","",Elenchi!AE3)
A37: Centro di Costo | C37: =IF(B37="","",Elenchi!AC3) | D37: ▼
A38: Indirizzo sede | D38: ▼
A39: Cod. e Città sede | B39: =IF(C38="","",Elenchi!Z3) | C39: =IF(C38="","",Elenchi!X3)
A40: In caso di uscita è previsto nuovo ingresso come
A41: Nuovo Referente diretto
...

Sheet Sicurezza
A1: COGNOME | B1: NOME | C1: CODICE FISCALE | D1: SESSO | E1: DATA NASCITA | F1: COMUNE | G1: PROV | H1: NAZ | I1: DATA Decorrenza | J1: DATA FINE RAPPORTO | K1: STATO | L1: SOCIETA' | M1: CDC | N1: CITTA DELLA SEDE DI APPARTENENZA | O1: INDIRIZZO SEDE | P1: AREA | Q1: CONTRATTO | R1: QUALIFICA | S1: TELELAVORO | T1: CODICE MANSIONE | U1: DESCRIZIONE MANSIONE | V1: REFERENTE | W1: NOMINA SICUREZZA | X1: DATA ASSEGNAZIONE NOMINA SICUREZZA
A2: =IF('Scheda Movimento'!C7="","",'Scheda Movimento'!C7) -> IACOVELLI | B2: =IF('Scheda Movimento'!C8="","",'Scheda Movimento'!C8) -> ALESSANDRA | C2: =IF('Scheda Movimento'!C10="","",'Scheda Movimento'!C10) -> CVLLSN80R49D643R | D2: =IF('Scheda Movimento'!C9="","",'Scheda Movimento'!B9) -> F | E2: =IF('Scheda Movimento'!C11="","",'Scheda Movimento'!C11) -> 29503 | F2: =IF('Scheda Movimento'!C12="","",'Scheda Movimento'!C12) -> FOGGIA | G2: =IF('Scheda Movimento'!C13="","",'Scheda Movimento'!C13) -> FOGGIA | H2: =IF('Scheda Movimento'!C14="","",'Scheda Movimento'!C14) -> ITALIA | I2: =IF('Scheda Movimento'!C5="","",'Scheda Movimento'!C5) -> 46097 | J2: =IF('Scheda Movimento'!C29="","",'Scheda Movimento'!C29) | K2: =IF('Scheda Movimento'!C28="","",'Scheda Movimento'!B28) -> S | L2: =IF('Scheda Movimento'!C15="","",IF(LEFT('Scheda Movimento'!C15,5)="Stage",SUBSTITUTE('Scheda Movimento'!C15,"Stage ",,1),IF(LEFT('Scheda Movimento'!C15,5)="Colla",SUBSTITUTE('Scheda Movimento'!C15,"Collaboratori - ",,1),IF(LEFT('Scheda Movimento'!C15,5)="Colla",SUBSTITUTE('Scheda Movimento'!C15,"Collaboratori ",,1),IF(LEFT('Scheda Movimento'!C15,5)="Inter",SUBSTITUTE('Scheda Movimento'!C15,"Interinali ",,1),'Scheda Movimento'!C15))))) -> IL SOLE 24 ORE S.P.A. | M2: =IF('Scheda Movimento'!B18="","",'Scheda Movimento'!B18) -> 415300 | N2: =IF('Scheda Movimento'!C20="","",'Scheda Movimento'!C20) -> MILANO | O2: =IF('Scheda Movimento'!C19="","",'Scheda Movimento'!C19) -> VIALE SARCA 223 - MILANO (MI) | P2: =IF('Scheda Movimento'!C16="","",'Scheda Movimento'!C16) -> DG I&S - DIR INFORMATION TECHNOLOGY | Q2: =IF('Scheda Movimento'!C21="","",'Scheda Movimento'!B21) -> 02 | R2: =IF('Scheda Movimento'!B22="","",IF(OR('Scheda Movimento'!B22="I",'Scheda Movimento'!B22="D",'Scheda Movimento'!B22="G",'Scheda Movimento'!B22="O",'Scheda Movimento'!B22="P",),'Scheda Movimento'!B22,"")) -> D | S2: =IF('Scheda Movimento'!C24="","",'Scheda Movimento'!C24) -> NO | T2: =IF('Scheda Movimento'!B31="","",'Scheda Movimento'!B31) -> IMP_VDT | U2: =IF('Scheda Movimento'!C31="","",'Scheda Movimento'!C31) -> IMPIEGATO CON USO VDT | V2: =IF('Scheda Movimento'!C33="","",'Scheda Movimento'!C33) -> Boromei Paola

Sheet Organizz
A1: SocietàOrg | B1: Unità Organizzativa | C1: Unità Organizzativa 2 | D1: Testata GG | E1: Testata 2 | F1: IncaricoSGSL | G1: CdC | H1: CdC2 | I1: ALTRI INCARICHI | J1: Titolare | K1: DettaglioTitolare | L1: Titolare 2 | M1: Cognome 2 | N1: Note Txt | O1: Note Txt 2 | P1: Note su Unità | Q1: Sede | R1: Sede 2 | S1: Tipo Collaborazione | T1: Maternità | U1: Processo | V1: Format | W1: Funzione | X1: AllegatiDip | Y1: Art GG | Z1: Tipo GG | AA1: Fte | AB1: ID | AC1: ReportsTo | AD1: Foto | AE1: Variazioni Posizione | AF1: TxCodFiscale | AG1: Cognome | AH1: Nome | AI1: Società | AJ1: Area | AK1: SottoArea | AL1: CdcAmministrazione | AM1: Descrizione Cdc | AN1: Data-ass | AO1: Data fine rapporto | AP1: Sesso | AQ1: Contratto | AR1: Qualifica | AS1: Livello | AT1: Testata giornalistica | AU1: Indirizzo | AV1: CAP | AW1: Città | AX1: Timb-fir | AY1: Turno | AZ1: RAL | BA1: Data Nascita | BB1: ETA' | BC1: Job-title | BD1: Liv-studio | BE1: Assenza | BF1: Responsabilediretto | BG1: TD-Sost | BH1: Part-time | BI1: email | BJ1: Numero | BK1: Cognome_email | BL1: Nome_email | BM1: email | BN1: INFO email | BO1: Dipendente email | BP1: TOP?verificarli | BQ1: Scelti | BR1: Scelti2 Tutti | BS1: Escluso da TNS | BT1: Popolaz_TNS | BU1: Deltacdc_TNS | BV1: CDC_TNS | BW1: CDC_NEW_TNS | BX1: Tipo Approvatore TNS | BY1: Note Appr NTS | BZ1: Titolare_TNS | CA1: LIVELLO_TNS | CB1: COD_TNS | CC1: PADRE_TNS | CD1: RUOLI_OltreV_TNS | CE1: RUOLI | CF1: Viaggiatore_TNS | CG1: Segr_Redaz_TNS | CH1: Approvatore_TNS | CI1: Cassiere_TNS | CJ1: Visualizzatori_TNS | CK1: Segretario_TNS | CL1: Controllore_TNS | CM1: Amministrazione_TNS | CN1: SegreteriA_Red_Assta_TNS | CO1: SegretariO_Assto_TNS | CP1: Controllore_Assto_TNS | CQ1: RuoliAFC | CR1: RuoliHR | CS1: AltriRuoli | CT1: Sede_TNS | CU1: GruppoSind | CV1: Controllo | CW1: RespAreaCODFIS | CX1: RespAreaCOGN | CY1: RespAreaNOM | CZ1: RespSottoareaCODFIS | DA1: RespSottoareaCOGN | DB1: RespSottoareaNOM | DC1: SBCAP | DD1: Escluso SF | DE1: Popolazione SF | DF1: Cogn | DG1: Nome | DH1: TxCodFisc | DI1: Richiedente SF | DJ1: Ricevente_Cognome | DK1: Ricevente_Nome | DL1: Ricevente_CodFis | DM1: Note | DN1: NO_ORG1e2liv | DO1: New posizione dopo | DP1: Free | DQ1: Titolare_SGSL | DR1: Ruolo_SGSL | DS1: SGSL_SI | DT1: NOME_UNITASGSL | DU1: ID_SGSL | DV1: CODPADRE_SGSL | DW1: Titolare_Privacy | DX1: Ruolo_Privacy | DY1: Privacy_SI | DZ1: NOME_UNITAPrivacy | EA1: ID_Privacy | EB1: CODPADRE_Privacy | EC1: Ruolo in SB/CAP | ED1: Ruolo in GeCo | EE1: Ruolo in procedure IT
A2: =AI2 -> IL SOLE 24 ORE S.P.A. | B2: =AM2 -> DIR INFORMATION TECHNOLOGY | G2: =AL2 -> 415300 | J2: =IF(AG2="","",CONCATENATE(LEFT(AG2,1),LOWER(REPLACE(AG2,1,1,""))," ",LEFT(AH2,1),". ")) -> Iacovelli A. | K2: =IF(OR('Scheda Movimento'!C34<>"",'Scheda Movimento'!B37<>"",'Scheda Movimento'!C40<>"",'Scheda Movimento'!B42<>"",'Scheda Movimento'!C43<>""),CONCATENATE('Scheda Movimento'!C34," - ",'Scheda Movimento'!B37," - ",'Scheda Movimento'!C40," - ",'Scheda Movimento'!B42," - ",'Scheda Movimento'!C43," - ",),"") | X2: =IF(AE2="","",AE2) -> INGRESSO | AB2: =IF(AF2="","",CONCATENATE(AF2,"_ID")) -> CVLLSN80R49D643R_ID | AE2: =IF('Scheda Movimento'!C6="","",'Scheda Movimento'!C6) -> INGRESSO | AF2: =IF('Scheda Movimento'!C10="","",'Scheda Movimento'!C10) -> CVLLSN80R49D643R | AG2: =IF('Scheda Movimento'!C7="","",'Scheda Movimento'!C7) -> IACOVELLI | AH2: =IF('Scheda Movimento'!C8="","",'Scheda Movimento'!C8) -> ALESSANDRA | AI2: =IF('Scheda Movimento'!C15="","",'Scheda Movimento'!C15) -> IL SOLE 24 ORE S.P.A. | AJ2: =IF('Scheda Movimento'!C16="","",'Scheda Movimento'!C16) -> DG I&S - DIR INFORMATION TECHNOLOGY | AK2: =IF('Scheda Movimento'!C17="","",'Scheda Movimento'!C17) -> DIR INFORMATION TECHNOLOGY | AL2: =IF('Scheda Movimento'!B18="","",'Scheda Movimento'!B18) -> 415300 | AM2: =IF('Scheda Movimento'!C18="","",'Scheda Movimento'!C18) -> DIR INFORMATION TECHNOLOGY | AN2: =IF('Scheda Movimento'!C5="","",'Scheda Movimento'!C5) -> 46097 | AO2: =IF('Scheda Movimento'!C29="","",'Scheda Movimento'!C29) | AP2: =IF('Scheda Movimento'!C9="","",'Scheda Movimento'!C9) -> Femminile | AR2: =IF('Scheda Movimento'!C22="","",IF('Scheda Movimento'!C22="Co.Co.Co.","Lav.Prog.",IF('Scheda Movimento'!C22="Co.Co.Pro.","Lav.Prog.",IF('Scheda Movimento'!C22="Contr","C.Somm.",'Scheda Movimento'!C22)))) -> DIRIGENTE | AS2: =IF('Scheda Movimento'!C22="Co.Co.Co.","COCOCO",IF('Scheda Movimento'!C22="Co.Co.Pro.","COLAPRO","")) | AU2: =IF('Scheda Movimento'!C19="","",'Scheda Movimento'!C19) -> VIALE SARCA 223 - MILANO (MI) | AW2: =IF('Scheda Movimento'!C20="","",'Scheda Movimento'!C20) -> MILANO | BC2: =IF('Scheda Movimento'!C30="","",'Scheda Movimento'!C30) | BF2: ='Scheda Movimento'!C33 -> Boromei Paola | BG2: =IF('Scheda Movimento'!C21="","",IF('Scheda Movimento'!C21="Contratto a tempo determinato","T.det","")) | BK2: =AG2 -> IACOVELLI | BL2: =AH2 -> ALESSANDRA | BM2: =IF(AG2="","",CONCATENATE(LEFT(AG2,1),LOWER(REPLACE(AG2,1,1,""))," ",_xlfn.TEXTBEFORE(LOWER(REPLACE(AH2,1,,""))," "))) -> #N/A | BN2: ='Scheda Movimento'!C27 -> alessandra.iacovelli@ilsole24ore.com | BT2: =IF(BS2<>"","",IF(OR(TRIM(AR2)="Dirigente",TRIM(AR2)="Quadro",TRIM(AR2)="Impiegato",TRIM(AR2)="Operaio",TRIM(AR2)="Giornalista"),"SI","")) -> SI | BZ2: =IF(BT2="","",CONCATENATE(TRIM(BK2)," ",TRIM(BL2))) -> IACOVELLI ALESSANDRA | CB2: =IF(BZ2="","",AF2) -> CVLLSN80R49D643R | CF2: =IF(CB2="","",IF(OR(AR2="GIORNALISTA",AR2="PRATICANTE"),"VG",IF(OR(AR2="IMPIEGATO",AR2="DIRIGENTE",AR2="OPERAIO"),"V",""))) -> V

Sheet Indicazioni per compilazione
A1: Indicazioni per la compilazione
B2: Dipendente | I2: Collaboratore
A3: Voci movimento | B3: Ingresso | C3: Ingresso + Distacco | D3: Trasfer.to | E3: Distacco | F3: Proroga | G3: Cambio Contratto | H3: Uscita | I3: Ingresso | J3: Proroga | K3: Cambio Contratto | L3: Uscita | M3: Voci movimento
A4: Decorrenza [data] | M4: Decorrenza [data]
A5: Movimento | M5: Movimento
A6: Cognome | M6: Cognome
A7: Nome | M7: Nome
A8: Sesso | M8: Sesso
A9: Codice Fiscale | M9: Codice Fiscale
A10: Data di nascita | M10: Data di nascita
A11: Comune di nascita | M11: Comune di nascita
A12: Provincia di nascita | M12: Provincia di nascita
A13: Nazione di nascita | M13: Nazione di nascita
A14: Società | M14: Società
A15: Area | M15: Area
... A35: Note | M35: Note
A37: (*) Valore definitivo a cura unità Sicurezza e Ambiente | B37: Legenda
D38: Ok da compilare
D39: Facoltativo
D40: Non necessario

Sheet Elenchi
D1: DESTINAZIONE (da Pivot) | L1: DESTINAZIONE (da Pivot) | R1: Aggiutno a mano | T1: PROVENIENZA (da Pivot) | AB1: PROVENIENZA
D3: ='Scheda Movimento'!C15 -> IL SOLE 24 ORE S.P.A. | E3: =VLOOKUP(D3,D5:E21,2,FALSE) -> 15 | G3: ='Scheda Movimento'!C19 -> VIALE SARCA 223 - MILANO (MI) | H3: =VLOOKUP(G3,G5:J29,2,FALSE) -> MILANO | I3: =VLOOKUP(G3,G5:J29,3,FALSE) -> MILANO | J3: =VLOOKUP(G3,G5:J29,4,FALSE) -> 34 | L3: ='Scheda Movimento'!B18 -> 415300 | M3: =VLOOKUP(L3,L6:M228,2,FALSE) -> DIR INFORMATION TECHNOLOGY | N3: =VLOOKUP(L3,L6:N228,3,FALSE) | O3: =VLOOKUP(L3,L6:O228,4,FALSE) -> DIR INFORMATION TECHNOLOGY | P3: =VLOOKUP(L3,L6:P228,5,FALSE) | Q3: =VLOOKUP(L3,L6:Q228,6,FALSE) -> DG I&S - DIR INFORMATION TECHNOLOGY | T3: ='Scheda Movimento'!C34 -> 0 | U3: =VLOOKUP(T3,T5:U19,2,FALSE) -> #N/A | W3: ='Scheda Movimento'!C38 -> 0 | X3: =VLOOKUP(W3,W5:Z27,2,FALSE) -> #N/A | Y3: =VLOOKUP(W3,W5:Z27,3,FALSE) -> #N/A | Z3: =VLOOKUP(W3,W5:Z27,4,FALSE) -> #N/A | AB3: ='Scheda Movimento'!B37 -> 0 | AC3: =VLOOKUP(AB3,AB6:AC228,2,FALSE) -> #N/A | AD3: =VLOOKUP(AB3,AB6:AD228,3,FALSE) -> #N/A | AE3: =VLOOKUP(AB3,AB6:AE228,4,FALSE) -> #N/A | AF3: =VLOOKUP(AB3,AB6:AF228,5,FALSE) -> #N/A | AG3: =VLOOKUP(AB3,AB6:AG228,6,FALSE) -> #N/A
A4: MOVIMENTI | D4: SOCIETA' | E4: COD SOCIETA' | G4: Via | H4: Citta | I4: Prov | J4: Codice Sede | L4: cdc | M4: descrcdc | N4: Codsottoarea | O4: Sottoare | P4: CodArea | Q4: Area | T4: SOCIETA' | U4: COD SOCIETA' | W4: Via | X4: Citta | Y4: Prov | Z4: Codice Sede | AB4: cdc | AC4: descrcdc | AD4: Codsottoarea | AE4: Sottoare | AF4: CodArea | AG4: Area
W5: =IF(G5="","",G5) | Y5: =IF(I5="","",I5) | Z5: =IF(J5="","",J5)
A6: CAMBIO CONTRATTO | D6: =IF('Pivot elenchi'!D3="","",'Pivot elenchi'!D3) -> IL SOLE 24 ORE S.P.A. | E6: =IF('Pivot elenchi'!C3="","",'Pivot elenchi'!C3) -> 15 | G6: =IF('Pivot elenchi'!I3="","",'Pivot elenchi'!I3) -> VIA TORTONA 56 - MILANO (MI) | H6: MILANO | I6: =IF('Pivot elenchi'!J3="","",'Pivot elenchi'!J3) -> MILANO | J6: =IF('Pivot elenchi'!H3="","",'Pivot elenchi'!H3) -> 19 | L6: =IF(AND('Pivot elenchi'!P5="",'Pivot elenchi'!P6=""),"",IF('Pivot elenchi'!P5="",'Pivot elenchi'!P4="",'Pivot elenchi'!P5)) -> 011000 | M6: =IF(AND('Pivot elenchi'!Q5="",'Pivot elenchi'!Q6=""),"",IF('Pivot elenchi'!Q5="",'Pivot elenchi'!Q4="",'Pivot elenchi'!Q5)) -> CORPORATE | N6: =IF(AND('Pivot elenchi'!R5="",'Pivot elenchi'!R6=""),"",IF('Pivot elenchi'!R5="",'Pivot elenchi'!R4="",'Pivot elenchi'!R5)) | O6: =IF(AND('Pivot elenchi'!S5="",'Pivot elenchi'!S6=""),"",IF('Pivot elenchi'!S5="",'Pivot elenchi'!S4="",'Pivot elenchi'!S5)) -> CORPORATE | P6: =IF(AND('Pivot elenchi'!T5="",'Pivot elenchi'!T6=""),"",IF('Pivot elenchi'!T5="",'Pivot elenchi'!T4="",'Pivot elenchi'!T5)) | Q6: =IF(AND('Pivot elenchi'!U5="",'Pivot elenchi'!U6=""),"",IF('Pivot elenchi'!U5="",'Pivot elenchi'!U4="",'Pivot elenchi'!U5)) -> CORPORATE | R6: @ilsole24ore.com | T6: =IF('Pivot elenchi'!D3="","",'Pivot elenchi'!D3) -> IL SOLE 24 ORE S.P.A. | U6: =IF('Pivot elenchi'!C3="","",'Pivot elenchi'!C3) -> 15 | W6: =IF(G6="","",G6) -> VIA TORTONA 56 - MILANO (MI) | X6: =IF(H6="","",H6) -> MILANO | Y6: =IF(I6="","",I6) -> MILANO | Z6: =IF(J6="","",J6) -> 19 | AB6: =L6 -> 011000 | AC6: =M6 -> CORPORATE | AD6: =N6 | AE6: =O6 -> CORPORATE | AF6: =P6 | AG6: =Q6 -> CORPORATE
A7: DISTACCO | D7: =IF('Pivot elenchi'!D4="","",'Pivot elenchi'!D4) -> 24 ORE CULTURA S.R.L. | E7: =IF('Pivot elenchi'!C4="","",'Pivot elenchi'!C4) -> 28 | G7: =IF('Pivot elenchi'!I4="","",'Pivot elenchi'!I4) -> PIAZZA INDIPENDENZA 23 B/C - ROMA (RM) | H7: ROMA | I7: =IF('Pivot elenchi'!J4="","",'Pivot elenchi'!J4) -> ROMA | J7: =IF('Pivot elenchi'!H4="","",'Pivot elenchi'!H4) -> 31 | L7: =IF(AND('Pivot elenchi'!P6="",'Pivot elenchi'!P7=""),"",IF('Pivot elenchi'!P6="",'Pivot elenchi'!P5="",'Pivot elenchi'!P6)) -> 011200 | M7: =IF(AND('Pivot elenchi'!Q6="",'Pivot elenchi'!Q7=""),"",IF('Pivot elenchi'!Q6="",'Pivot elenchi'!Q5="",'Pivot elenchi'!Q6)) -> DG INNOVAZIONE E SOSTENIBILITA' | N7: =IF(AND('Pivot elenchi'!R6="",'Pivot elenchi'!R7=""),"",IF('Pivot elenchi'!R6="",'Pivot elenchi'!R5="",'Pivot elenchi'!R6)) | O7: =IF(AND('Pivot elenchi'!S6="",'Pivot elenchi'!S7=""),"",IF('Pivot elenchi'!S6="",'Pivot elenchi'!S5="",'Pivot elenchi'!S6)) -> DG INNOVAZIONE E SOSTENIBILITA' | P7: =IF(AND('Pivot elenchi'!T6="",'Pivot elenchi'!T7=""),"",IF('Pivot elenchi'!T6="",'Pivot elenchi'!T5="",'Pivot elenchi'!T6)) | Q7: =IF(AND('Pivot elenchi'!U6="",'Pivot elenchi'!U7=""),"",IF('Pivot elenchi'!U6="",'Pivot elenchi'!U5="",'Pivot elenchi'!U6)) -> DG INNOVAZIONE E SOSTENIBILITA' | R7: @ilsole24ore.com | T7: =IF('Pivot elenchi'!D4="","",'Pivot elenchi'!D4) -> 24 ORE CULTURA S.R.L. | U7: =IF('Pivot elenchi'!C4="","",'Pivot elenchi'!C4) -> 28 | W7: =IF(G7="","",G7) -> PIAZZA INDIPENDENZA 23 B/C - ROMA (RM) | X7: =IF(H7="","",H7) -> ROMA | Y7: =IF(I7="","",I7) -> ROMA | Z7: =IF(J7="","",J7) -> 31 | AB7: =L7 -> 011200 | AC7: =M7 -> DG INNOVAZIONE E SOSTENIBILITA' | AD7: =N7 | AE7: =O7 -> DG INNOVAZIONE E SOSTENIBILITA' | AF7: =P7 | AG7: =Q7 -> DG INNOVAZIONE E SOSTENIBILITA'
A8: DISTACCO - FINE | D8: =IF('Pivot elenchi'!D5="","",'Pivot elenchi'!D5) -> IL SOLE 24 ORE EVENTI S.R.L. | E8: =IF('Pivot elenchi'!C5="","",'Pivot elenchi'!C5) -> 35 | G8: =IF('Pivot elenchi'!I5="","",'Pivot elenchi'!I5) -> VIA NIZZA 142 - ROMA (RM) | H8: ROMA | I8: =IF('Pivot elenchi'!J5="","",'Pivot elenchi'!J5) -> ROMA | J8: =IF('Pivot elenchi'!H5="","",'Pivot elenchi'!H5) -> 33 | L8: =IF(AND('Pivot elenchi'!P7="",'Pivot elenchi'!P8=""),"",IF('Pivot elenchi'!P7="",'Pivot elenchi'!P6="",'Pivot elenchi'!P7)) -> 012000 | M8: =IF(AND('Pivot elenchi'!Q7="",'Pivot elenchi'!Q8=""),"",IF('Pivot elenchi'!Q7="",'Pivot elenchi'!Q6="",'Pivot elenchi'!Q7)) -> AFFARI LEGALI E SOCIETARI | N8: =IF(AND('Pivot elenchi'!R7="",'Pivot elenchi'!R8=""),"",IF('Pivot elenchi'!R7="",'Pivot elenchi'!R6="",'Pivot elenchi'!R7)) | O8: =IF(AND('Pivot elenchi'!S7="",'Pivot elenchi'!S8=""),"",IF('Pivot elenchi'!S7="",'Pivot elenchi'!S6="",'Pivot elenchi'!S7)) -> AFFARI LEGALI E SOCIETARI | P8: =IF(AND('Pivot elenchi'!T7="",'Pivot elenchi'!T8=""),"",IF('Pivot elenchi'!T7="",'Pivot elenchi'!T6="",'Pivot elenchi'!T7)) | Q8: =IF(AND('Pivot elenchi'!U7="",'Pivot elenchi'!U8=""),"",IF('Pivot elenchi'!U7="",'Pivot elenchi'!U6="",'Pivot elenchi'!U7)) -> AFFARI LEGALI E SOCIETARI | R8: @ilsole24ore.com | T8: =IF('Pivot elenchi'!D5="","",'Pivot elenchi'!D5) -> IL SOLE 24 ORE EVENTI S.R.L. | U8: =IF('Pivot elenchi'!C5="","",'Pivot elenchi'!C5) -> 35 | W8: =IF(G8="","",G8) -> VIA NIZZA 142 - ROMA (RM) | X8: =IF(H8="","",H8) -> ROMA | Y8: =IF(I8="","",I8) -> ROMA | Z8: =IF(J8="","",J8) -> 33 | AB8: =L8 -> 012000 | AC8: =M8 -> AFFARI LEGALI E SOCIETARI | AD8: =N8 | AE8: =O8 -> AFFARI LEGALI E SOCIETARI | AF8: =P8 | AG8: =Q8 -> AFFARI LEGALI E SOCIETARI
A9: INGRESSO | D9: =IF('Pivot elenchi'!D6="","",'Pivot elenchi'!D6) -> IL SOLE 24 ORE SPA | E9: =IF('Pivot elenchi'!C6="","",'Pivot elenchi'!C6) -> 2015 | G9: =IF('Pivot elenchi'!I6="","",'Pivot elenchi'!I6) -> VIALE SARCA 223 - MILANO (MI) | H9: MILANO | I9: =IF('Pivot elenchi'!J6="","",'Pivot elenchi'!J6) -> MILANO | J9: =IF('Pivot elenchi'!H6="","",'Pivot elenchi'!H6) -> 34 | L9: =IF(AND('Pivot elenchi'!P8="",'Pivot elenchi'!P9=""),"",IF('Pivot elenchi'!P8="",'Pivot elenchi'!P7="",'Pivot elenchi'!P8)) -> 013000 | M9: =IF(AND('Pivot elenchi'!Q8="",'Pivot elenchi'!Q9=""),"",IF('Pivot elenchi'!Q8="",'Pivot elenchi'!Q7="",'Pivot elenchi'!Q8)) -> INVESTOR RELATIONS | N9: =IF(AND('Pivot elenchi'!R8="",'Pivot elenchi'!R9=""),"",IF('Pivot elenchi'!R8="",'Pivot elenchi'!R7="",'Pivot elenchi'!R8)) | O9: =IF(AND('Pivot elenchi'!S8="",'Pivot elenchi'!S9=""),"",IF('Pivot elenchi'!S8="",'Pivot elenchi'!S7="",'Pivot elenchi'!S8)) -> INVESTOR RELATIONS | P9: =IF(AND('Pivot elenchi'!T8="",'Pivot elenchi'!T9=""),"",IF('Pivot elenchi'!T8="",'Pivot elenchi'!T7="",'Pivot elenchi'!T8)) | Q9: =IF(AND('Pivot elenchi'!U8="",'Pivot elenchi'!U9=""),"",IF('Pivot elenchi'!U8="",'Pivot elenchi'!U7="",'Pivot elenchi'!U8)) -> AMMINISTRAZIONE, FINANZA E CONTROLLO | R9: @ilsole24ore.com | T9: =IF('Pivot elenchi'!D6="","",'Pivot elenchi'!D6) -> IL SOLE 24 ORE SPA | U9: =IF('Pivot elenchi'!C6="","",'Pivot elenchi'!C6) -> 2015 | W9: =IF(G9="","",G9) -> VIALE SARCA 223 - MILANO (MI) | X9: =IF(H9="","",H9) -> MILANO | Y9: =IF(I9="","",I9) -> MILANO | Z9: =IF(J9="","",J9) -> 34 | AB9: =L9 -> 013000 | AC9: =M9 -> INVESTOR RELATIONS | AD9: =N9 | AE9: =O9 -> INVESTOR RELATIONS | AF9: =P9 | AG9: =Q9 -> AMMINISTRAZIONE, FINANZA E CONTROLLO
A10: INGRESSO CON DISTACCO | D10: =IF('Pivot elenchi'!D7="","",'Pivot elenchi'!D7) -> COLLABORATORI 24ORE CULTURA | E10: =IF('Pivot elenchi'!C7="","",'Pivot elenchi'!C7) -> 2028 | G10: =IF('Pivot elenchi'!I7="","",'Pivot elenchi'!I7) -> VIA DAVIDE BERTOLOTTI 7 - TORINO (TO) | H10: TORINO | I10: =IF('Pivot elenchi'!J7="","",'Pivot elenchi'!J7) -> TORINO | J10: =IF('Pivot elenchi'!H7="","",'Pivot elenchi'!H7) -> 50 | L10: =IF(AND('Pivot elenchi'!P9="",'Pivot elenchi'!P10=""),"",IF('Pivot elenchi'!P9="",'Pivot elenchi'!P8="",'Pivot elenchi'!P9)) -> 015000 | M10: =IF(AND('Pivot elenchi'!Q9="",'Pivot elenchi'!Q10=""),"",IF('Pivot elenchi'!Q9="",'Pivot elenchi'!Q8="",'Pivot elenchi'!Q9)) -> DG SERVIZI PROFESSIONALI | N10: =IF(AND('Pivot elenchi'!R9="",'Pivot elenchi'!R10=""),"",IF('Pivot elenchi'!R9="",'Pivot elenchi'!R8="",'Pivot elenchi'!R9)) | O10: =IF(AND('Pivot elenchi'!S9="",'Pivot elenchi'!S10=""),"",IF('Pivot elenchi'!S9="",'Pivot elenchi'!S8="",'Pivot elenchi'!S9)) -> DG SERVIZI PROFESSIONALI E FORMAZIONE | P10: =IF(AND('Pivot elenchi'!T9="",'Pivot elenchi'!T10=""),"",IF('Pivot elenchi'!T9="",'Pivot elenchi'!T8="",'Pivot elenchi'!T9)) | Q10: =IF(AND('Pivot elenchi'!U9="",'Pivot elenchi'!U10=""),"",IF('Pivot elenchi'!U9="",'Pivot elenchi'!U8="",'Pivot elenchi'!U9)) -> DG SERVIZI PROFESSIONALI E FORMAZIONE | R10: @ilsole24ore.com | T10: =IF('Pivot elenchi'!D7="","",'Pivot elenchi'!D7) -> COLLABORATORI 24ORE CULTURA | U10: =IF('Pivot elenchi'!C7="","",'Pivot elenchi'!C7) -> 2028 | W10: =IF(G10="","",G10) -> VIA DAVIDE BERTOLOTTI 7 - TORINO (TO) | X10: =IF(H10="","",H10) -> TORINO | Y10: =IF(I10="","",I10) -> TORINO | Z10: =IF(J10="","",J10) -> 50 | AB10: =L10 -> 015000 | AC10: =M10 -> DG SERVIZI PROFESSIONALI | AD10: =N10 | AE10: =O10 -> DG SERVIZI PROFESSIONALI E FORMAZIONE | AF10: =P10 | AG10: =Q10 -> DG SERVIZI PROFESSIONALI E FORMAZIONE
A11: PROROGA | D11: =IF('Pivot elenchi'!D8="","",'Pivot elenchi'!D8) -> IL SOLE 24 ORE SPA | E11: =IF('Pivot elenchi'!C8="","",'Pivot elenchi'!C8) -> 4015 | G11: =IF('Pivot elenchi'!I8="","",'Pivot elenchi'!I8) -> VIA SOLTERI 38 - TRENTO (TN) | H11: TRENTO | I11: =IF('Pivot elenchi'!J8="","",'Pivot elenchi'!J8) -> TRENTO | J11: =IF('Pivot elenchi'!H8="","",'Pivot elenchi'!H8) -> 65 | L11: =IF(AND('Pivot elenchi'!P10="",'Pivot elenchi'!P11=""),"",IF('Pivot elenchi'!P10="",'Pivot elenchi'!P9="",'Pivot elenchi'!P10)) -> 016100 | M11: =IF(AND('Pivot elenchi'!Q10="",'Pivot elenchi'!Q11=""),"",IF('Pivot elenchi'!Q10="",'Pivot elenchi'!Q9="",'Pivot elenchi'!Q10)) -> INTERNAL AUDITING | N11: =IF(AND('Pivot elenchi'!R10="",'Pivot elenchi'!R11=""),"",IF('Pivot elenchi'!R10="",'Pivot elenchi'!R9="",'Pivot elenchi'!R10)) | O11: =IF(AND('Pivot elenchi'!S10="",'Pivot elenchi'!S11=""),"",IF('Pivot elenchi'!S10="",'Pivot elenchi'!S9="",'Pivot elenchi'!S10)) -> INTERNAL AUDITING | P11: =IF(AND('Pivot elenchi'!T10="",'Pivot elenchi'!T11=""),"",IF('Pivot elenchi'!T10="",'Pivot elenchi'!T9="",'Pivot elenchi'!T10)) | Q11: =IF(AND('Pivot elenchi'!U10="",'Pivot elenchi'!U11=""),"",IF('Pivot elenchi'!U10="",'Pivot elenchi'!U9="",'Pivot elenchi'!U10)) -> CORPORATE | R11: @ilsole24ore.com | T11: =IF('Pivot elenchi'!D8="","",'Pivot elenchi'!D8) -> IL SOLE 24 ORE SPA | U11: =IF('Pivot elenchi'!C8="","",'Pivot elenchi'!C8) -> 4015 | W11: =IF(G11="","",G11) -> VIA SOLTERI 38 - TRENTO (TN) | X11: =IF(H11="","",H11) -> TRENTO | Y11: =IF(I11="","",I11) -> TRENTO | Z11: =IF(J11="","",J11) -> 65 | AB11: =L11 -> 016100 | AC11: =M11 -> INTERNAL AUDITING | AD11: =N11 | AE11: =O11 -> INTERNAL AUDITING | AF11: =P11 | AG11: =Q11 -> CORPORATE
A12: PROROGA DISTACCO | D12: =IF('Pivot elenchi'!D9="","",'Pivot elenchi'!D9) -> SOLE STAGE | E12: =IF('Pivot elenchi'!C9="","",'Pivot elenchi'!C9) -> 1010 | G12: =IF('Pivot elenchi'!I9="","",'Pivot elenchi'!I9) -> DOMICILIO COLLABORATORE - () | I12: =IF('Pivot elenchi'!J9="","",'Pivot elenchi'!J9) | J12: =IF('Pivot elenchi'!H9="","",'Pivot elenchi'!H9) -> 66 | L12: =IF(AND('Pivot elenchi'!P11="",'Pivot elenchi'!P12=""),"",IF('Pivot elenchi'!P11="",'Pivot elenchi'!P10="",'Pivot elenchi'!P11)) -> 016110 | M12: =IF(AND('Pivot elenchi'!Q11="",'Pivot elenchi'!Q12=""),"",IF('Pivot elenchi'!Q11="",'Pivot elenchi'!Q10="",'Pivot elenchi'!Q11)) -> PRIVACY E SICUREZZA DATI | N12: =IF(AND('Pivot elenchi'!R11="",'Pivot elenchi'!R12=""),"",IF('Pivot elenchi'!R11="",'Pivot elenchi'!R10="",'Pivot elenchi'!R11)) | O12: =IF(AND('Pivot elenchi'!S11="",'Pivot elenchi'!S12=""),"",IF('Pivot elenchi'!S11="",'Pivot elenchi'!S10="",'Pivot elenchi'!S11)) -> AFFARI LEGALI E SOCIETARI | P12: =IF(AND('Pivot elenchi'!T11="",'Pivot elenchi'!T12=""),"",IF('Pivot elenchi'!T11="",'Pivot elenchi'!T10="",'Pivot elenchi'!T11)) | Q12: =IF(AND('Pivot elenchi'!U11="",'Pivot elenchi'!U12=""),"",IF('Pivot elenchi'!U11="",'Pivot elenchi'!U10="",'Pivot elenchi'!U11)) -> AFFARI LEGALI E SOCIETARI | R12: @ilsole24ore.com | T12: =IF('Pivot elenchi'!D9="","",'Pivot elenchi'!D9) -> SOLE STAGE | U12: =IF('Pivot elenchi'!C9="","",'Pivot elenchi'!C9) -> 1010 | W12: =IF(G12="","",G12) -> DOMICILIO COLLABORATORE - () | X12: =IF(H12="","",H12) | Y12: =IF(I12="","",I12) | Z12: =IF(J12="","",J12) -> 66 | AB12: =L12 -> 016110 | AC12: =M12 -> PRIVACY E SICUREZZA DATI | AD12: =N12 | AE12: =O12 -> AFFARI LEGALI E SOCIETARI | AF12: =P12 | AG12: =Q12 -> AFFARI LEGALI E SOCIETARI
A13: TRASFERIMENTO | D13: =IF('Pivot elenchi'!D10="","",'Pivot elenchi'!D10) | E13: =IF('Pivot elenchi'!C10="","",'Pivot elenchi'!C10) | G13: =IF('Pivot elenchi'!I10="","",'Pivot elenchi'!I10) -> VIA DELLE LIBERTA' 12 - VENEZIA (VE) | H13: VENEZIA | I13: =IF('Pivot elenchi'!J10="","",'Pivot elenchi'!J10) -> VENEZIA | J13: =IF('Pivot elenchi'!H10="","",'Pivot elenchi'!H10) -> 68 | L13: =IF(AND('Pivot elenchi'!P12="",'Pivot elenchi'!P13=""),"",IF('Pivot elenchi'!P12="",'Pivot elenchi'!P11="",'Pivot elenchi'!P12)) -> 210000 | M13: =IF(AND('Pivot elenchi'!Q12="",'Pivot elenchi'!Q13=""),"",IF('Pivot elenchi'!Q12="",'Pivot elenchi'!Q11="",'Pivot elenchi'!Q12)) -> AMMINISTRAZIONE, FINANZA E CONTROLLO | N13: =IF(AND('Pivot elenchi'!R12="",'Pivot elenchi'!R13=""),"",IF('Pivot elenchi'!R12="",'Pivot elenchi'!R11="",'Pivot elenchi'!R12)) | O13: =IF(AND('Pivot elenchi'!S12="",'Pivot elenchi'!S13=""),"",IF('Pivot elenchi'!S12="",'Pivot elenchi'!S11="",'Pivot elenchi'!S12)) -> AMMINISTRAZIONE, FINANZA E CONTROLLO | P13: =IF(AND('Pivot elenchi'!T12="",'Pivot elenchi'!T13=""),"",IF('Pivot elenchi'!T12="",'Pivot elenchi'!T11="",'Pivot elenchi'!T12)) | Q13: =IF(AND('Pivot elenchi'!U12="",'Pivot elenchi'!U13=""),"",IF('Pivot elenchi'!U12="",'Pivot elenchi'!U11="",'Pivot elenchi'!U12)) -> AMMINISTRAZIONE, FINANZA E CONTROLLO | R13: @ilsole24ore.com | T13: =IF('Pivot elenchi'!D10="","",'Pivot elenchi'!D10) | U13: =IF('Pivot elenchi'!C10="","",'Pivot elenchi'!C10) | W13: =IF(G13="","",G13) -> VIA DELLE LIBERTA' 12 - VENEZIA (VE) | X13: =IF(H13="","",H13) -> VENEZIA | Y13: =IF(I13="","",I13) -> VENEZIA | Z13: =IF(J13="","",J13) -> 68 | AB13: =L13 -> 210000 | AC13: =M13 -> AMMINISTRAZIONE, FINANZA E CONTROLLO | AD13: =N13 | AE13: =O13 -> AMMINISTRAZIONE, FINANZA E CONTROLLO | AF13: =P13 | AG13: =Q13 -> AMMINISTRAZIONE, FINANZA E CONTROLLO
A14: TRASFORMAZIONE CONTRATTO | D14: =IF('Pivot elenchi'!D11="","",'Pivot elenchi'!D11) | E14: =IF('Pivot elenchi'!C11="","",'Pivot elenchi'!C11) | G14: =IF('Pivot elenchi'!I11="","",'Pivot elenchi'!I11) -> VIA ALESSANDRO VOLTA 44 - PALERMO (PA) | H14: PALERMO | I14: =IF('Pivot elenchi'!J11="","",'Pivot elenchi'!J11) -> PALERMO | J14: =IF('Pivot elenchi'!H11="","",'Pivot elenchi'!H11) -> 72 | L14: =IF(AND('Pivot elenchi'!P13="",'Pivot elenchi'!P14=""),"",IF('Pivot elenchi'!P13="",'Pivot elenchi'!P12="",'Pivot elenchi'!P13)) -> 21000001 | M14: =IF(AND('Pivot elenchi'!Q13="",'Pivot elenchi'!Q14=""),"",IF('Pivot elenchi'!Q13="",'Pivot elenchi'!Q12="",'Pivot elenchi'!Q13)) -> FISCALITA' | N14: =IF(AND('Pivot elenchi'!R13="",'Pivot elenchi'!R14=""),"",IF('Pivot elenchi'!R13="",'Pivot elenchi'!R12="",'Pivot elenchi'!R13)) | O14: =IF(AND('Pivot elenchi'!S13="",'Pivot elenchi'!S14=""),"",IF('Pivot elenchi'!S13="",'Pivot elenchi'!S12="",'Pivot elenchi'!S13)) -> FISCALITA' | P14: =IF(AND('Pivot elenchi'!T13="",'Pivot elenchi'!T14=""),"",IF('Pivot elenchi'!T13="",'Pivot elenchi'!T12="",'Pivot elenchi'!T13)) | Q14: =IF(AND('Pivot elenchi'!U13="",'Pivot elenchi'!U14=""),"",IF('Pivot elenchi'!U13="",'Pivot elenchi'!U12="",'Pivot elenchi'!U13)) -> AMMINISTRAZIONE, FINANZA E CONTROLLO | R14: @ilsole24ore.com | T14: =IF('Pivot elenchi'!D11="","",'Pivot elenchi'!D11) | U14: =IF('Pivot elenchi'!C11="","",'Pivot elenchi'!C11) | W14: =IF(G14="","",G14) -> VIA ALESSANDRO VOLTA 44 - PALERMO (PA) | X14: =IF(H14="","",H14) -> PALERMO | Y14: =IF(I14="","",I14) -> PALERMO | Z14: =IF(J14="","",J14) -> 72 | AB14: =L14 -> 21000001 | AC14: =M14 -> FISCALITA' | AD14: =N14 | AE14: =O14 -> FISCALITA' | AF14: =P14 | AG14: =Q14 -> AMMINISTRAZIONE, FINANZA E CONTROLLO
A15: USCITA | D15: =IF('Pivot elenchi'!D12="","",'Pivot elenchi'!D12) | E15: =IF('Pivot elenchi'!C12="","",'Pivot elenchi'!C12) | G15: =IF('Pivot elenchi'!I12="","",'Pivot elenchi'!I12) -> PIAZZA DEI MARTIRI 58 - NAPOLI (NA) | H15: NAPOLI | I15: =IF('Pivot elenchi'!J12="","",'Pivot elenchi'!J12) -> NAPOLI | J15: =IF('Pivot elenchi'!H12="","",'Pivot elenchi'!H12) -> 79 | L15: =IF(AND('Pivot elenchi'!P14="",'Pivot elenchi'!P15=""),"",IF('Pivot elenchi'!P14="",'Pivot elenchi'!P13="",'Pivot elenchi'!P14)) -> 214000 | M15: =IF(AND('Pivot elenchi'!Q14="",'Pivot elenchi'!Q15=""),"",IF('Pivot elenchi'!Q14="",'Pivot elenchi'!Q13="",'Pivot elenchi'!Q14)) -> PIANIFICAZIONE E CONTROLLO DI G | N15: =IF(AND('Pivot elenchi'!R14="",'Pivot elenchi'!R15=""),"",IF('Pivot elenchi'!R14="",'Pivot elenchi'!R13="",'Pivot elenchi'!R14)) | O15: =IF(AND('Pivot elenchi'!S14="",'Pivot elenchi'!S15=""),"",IF('Pivot elenchi'!S14="",'Pivot elenchi'!S13="",'Pivot elenchi'!S14)) -> PIANIFICAZIONE E CONTROLLO | P15: =IF(AND('Pivot elenchi'!T14="",'Pivot elenchi'!T15=""),"",IF('Pivot elenchi'!T14="",'Pivot elenchi'!T13="",'Pivot elenchi'!T14)) | Q15: =IF(AND('Pivot elenchi'!U14="",'Pivot elenchi'!U15=""),"",IF('Pivot elenchi'!U14="",'Pivot elenchi'!U13="",'Pivot elenchi'!U14)) -> AMMINISTRAZIONE, FINANZA E CONTROLLO | R15: @ilsole24ore.com | T15: =IF('Pivot elenchi'!D12="","",'Pivot elenchi'!D12) | U15: =IF('Pivot elenchi'!C12="","",'Pivot elenchi'!C12) | W15: =IF(G15="","",G15) -> PIAZZA DEI MARTIRI 58 - NAPOLI (NA) | X15: =IF(H15="","",H15) -> NAPOLI | Y15: =IF(I15="","",I15) -> NAPOLI | Z15: =IF(J15="","",J15) -> 79 | AB15: =L15 -> 214000 | AC15: =M15 -> PIANIFICAZIONE E CONTROLLO DI G | AD15: =N15 | AE15: =O15 -> PIANIFICAZIONE E CONTROLLO | AF15: =P15 | AG15: =Q15 -> AMMINISTRAZIONE, FINANZA E CONTROLLO
D16: =IF('Pivot elenchi'!D13="","",'Pivot elenchi'!D13) | E16: =IF('Pivot elenchi'!C13="","",'Pivot elenchi'!C13) | G16: =IF('Pivot elenchi'!I13="","",'Pivot elenchi'!I13) -> VIALE IV NOVEMBRE 6 - GENOVA (GE) | H16: GENOVA | I16: =IF('Pivot elenchi'!J13="","",'Pivot elenchi'!J13) -> GENOVA | J16: =IF('Pivot elenchi'!H13="","",'Pivot elenchi'!H13) -> 80 | L16: =IF(AND('Pivot elenchi'!P15="",'Pivot elenchi'!P16=""),"",IF('Pivot elenchi'!P15="",'Pivot elenchi'!P14="",'Pivot elenchi'!P15)) -> 215000 | M16: =IF(AND('Pivot elenchi'!Q15="",'Pivot elenchi'!Q16=""),"",IF('Pivot elenchi'!Q15="",'Pivot elenchi'!Q14="",'Pivot elenchi'!Q15)) -> BILANCIO | N16: =IF(AND('Pivot elenchi'!R15="",'Pivot elenchi'!R16=""),"",IF('Pivot elenchi'!R15="",'Pivot elenchi'!R14="",'Pivot elenchi'!R15)) | O16: =IF(AND('Pivot elenchi'!S15="",'Pivot elenchi'!S16=""),"",IF('Pivot elenchi'!S15="",'Pivot elenchi'!S14="",'Pivot elenchi'!S15)) -> AMMINISTRAZIONE E BILANCIO | P16: =IF(AND('Pivot elenchi'!T15="",'Pivot elenchi'!T16=""),"",IF('Pivot elenchi'!T15="",'Pivot elenchi'!T14="",'Pivot elenchi'!T15)) | Q16: =IF(AND('Pivot elenchi'!U15="",'Pivot elenchi'!U16=""),"",IF('Pivot elenchi'!U15="",'Pivot elenchi'!U14="",'Pivot elenchi'!U15)) -> AMMINISTRAZIONE, FINANZA E CONTROLLO | R16: @ilsole24ore.com | T16: =IF('Pivot elenchi'!D13="","",'Pivot elenchi'!D13) | U16: =IF('Pivot elenchi'!C13="","",'Pivot elenchi'!C13) | W16: =IF(G16="","",G16) -> VIALE IV NOVEMBRE 6 - GENOVA (GE) | X16: =IF(H16="","",H16) -> GENOVA | Y16: =IF(I16="","",I16) -> GENOVA | Z16: =IF(J16="","",J16) -> 80 | AB16: =L16 -> 215000 | AC16: =M16 -> BILANCIO | AD16: =N16 | AE16: =O16 -> AMMINISTRAZIONE E BILANCIO | AF16: =P16 | AG16: =Q16 -> AMMINISTRAZIONE, FINANZA E CONTROLLO
D17: =IF('Pivot elenchi'!D14="","",'Pivot elenchi'!D14) | E17: =IF('Pivot elenchi'!C14="","",'Pivot elenchi'!C14) | G17: =IF('Pivot elenchi'!I14="","",'Pivot elenchi'!I14) -> Corrisp. ESTERO | H17: EE | I17: =IF('Pivot elenchi'!J14="","",'Pivot elenchi'!J14) -> EE | J17: =IF('Pivot elenchi'!H14="","",'Pivot elenchi'!H14) -> 99 | L17: =IF(AND('Pivot elenchi'!P16="",'Pivot elenchi'!P17=""),"",IF('Pivot elenchi'!P16="",'Pivot elenchi'!P15="",'Pivot elenchi'!P16)) -> 215100 | M17: =IF(AND('Pivot elenchi'!Q16="",'Pivot elenchi'!Q17=""),"",IF('Pivot elenchi'!Q16="",'Pivot elenchi'!Q15="",'Pivot elenchi'!Q16)) -> CREDIT MANAGEMENT | N17: =IF(AND('Pivot elenchi'!R16="",'Pivot elenchi'!R17=""),"",IF('Pivot elenchi'!R16="",'Pivot elenchi'!R15="",'Pivot elenchi'!R16)) | O17: =IF(AND('Pivot elenchi'!S16="",'Pivot elenchi'!S17=""),"",IF('Pivot elenchi'!S16="",'Pivot elenchi'!S15="",'Pivot elenchi'!S16)) -> FINANZA, TESORERIA E RISK MANAGEMENT | P17: =IF(AND('Pivot elenchi'!T16="",'Pivot elenchi'!T17=""),"",IF('Pivot elenchi'!T16="",'Pivot elenchi'!T15="",'Pivot elenchi'!T16)) | Q17: =IF(AND('Pivot elenchi'!U16="",'Pivot elenchi'!U17=""),"",IF('Pivot elenchi'!U16="",'Pivot elenchi'!U15="",'Pivot elenchi'!U16)) -> AMMINISTRAZIONE, FINANZA E CONTROLLO | R17: @ilsole24ore.com | T17: =IF('Pivot elenchi'!D14="","",'Pivot elenchi'!D14) | U17: =IF('Pivot elenchi'!C14="","",'Pivot elenchi'!C14) | W17: =IF(G17="","",G17) -> Corrisp. ESTERO | X17: =IF(H17="","",H17) -> EE | Y17: =IF(I17="","",I17) -> EE | Z17: =IF(J17="","",J17) -> 99 | AB17: =L17 -> 215100 | AC17: =M17 -> CREDIT MANAGEMENT | AD17: =N17 | AE17: =O17 -> FINANZA, TESORERIA E RISK MANAGEMENT | AF17: =P17 | AG17: =Q17 -> AMMINISTRAZIONE, FINANZA E CONTROLLO
A18: E-mail prefisso "EXT." | D18: =IF('Pivot elenchi'!D15="","",'Pivot elenchi'!D15) | E18: =IF('Pivot elenchi'!C15="","",'Pivot elenchi'!C15) | G18: =IF('Pivot elenchi'!I15="","",'Pivot elenchi'!I15) | I18: =IF('Pivot elenchi'!J15="","",'Pivot elenchi'!J15) | J18: =IF('Pivot elenchi'!H15="","",'Pivot elenchi'!H15) | L18: =IF(AND('Pivot elenchi'!P17="",'Pivot elenchi'!P18=""),"",IF('Pivot elenchi'!P17="",'Pivot elenchi'!P16="",'Pivot elenchi'!P17)) -> 21520011 | M18: =IF(AND('Pivot elenchi'!Q17="",'Pivot elenchi'!Q18=""),"",IF('Pivot elenchi'!Q17="",'Pivot elenchi'!Q16="",'Pivot elenchi'!Q17)) -> CONTABILITA' GENERALE | N18: =IF(AND('Pivot elenchi'!R17="",'Pivot elenchi'!R18=""),"",IF('Pivot elenchi'!R17="",'Pivot elenchi'!R16="",'Pivot elenchi'!R17)) | O18: =IF(AND('Pivot elenchi'!S17="",'Pivot elenchi'!S18=""),"",IF('Pivot elenchi'!S17="",'Pivot elenchi'!S16="",'Pivot elenchi'!S17)) -> AMMINISTRAZIONE E BILANCIO | P18: =IF(AND('Pivot elenchi'!T17="",'Pivot elenchi'!T18=""),"",IF('Pivot elenchi'!T17="",'Pivot elenchi'!T16="",'Pivot elenchi'!T17)) | Q18: =IF(AND('Pivot elenchi'!U17="",'Pivot elenchi'!U18=""),"",IF('Pivot elenchi'!U17="",'Pivot elenchi'!U16="",'Pivot elenchi'!U17)) -> AMMINISTRAZIONE, FINANZA E CONTROLLO | R18: @ilsole24ore.com | T18: =IF('Pivot elenchi'!D15="","",'Pivot elenchi'!D15) | U18: =IF('Pivot elenchi'!C15="","",'Pivot elenchi'!C15) | W18: =IF(G18="","",G18) | X18: =IF(H18="","",H18) | Y18: =IF(I18="","",I18) | Z18: =IF(J18="","",J18) | AB18: =L18 -> 21520011 | AC18: =M18 -> CONTABILITA' GENERALE | AD18: =N18 | AE18: =O18 -> AMMINISTRAZIONE E BILANCIO | AF18: =P18 | AG18: =Q18 -> AMMINISTRAZIONE, FINANZA E CONTROLLO
A19: Si EXT. | D19: =IF('Pivot elenchi'!D16="","",'Pivot elenchi'!D16) | E19: =IF('Pivot elenchi'!C16="","",'Pivot elenchi'!C16) | G19: =IF('Pivot elenchi'!I16="","",'Pivot elenchi'!I16) | I19: =IF('Pivot elenchi'!J16="","",'Pivot elenchi'!J16) | J19: =IF('Pivot elenchi'!H16="","",'Pivot elenchi'!H16) | L19: =IF(AND('Pivot elenchi'!P18="",'Pivot elenchi'!P19=""),"",IF('Pivot elenchi'!P18="",'Pivot elenchi'!P17="",'Pivot elenchi'!P18)) -> 21520012 | M19: =IF(AND('Pivot elenchi'!Q18="",'Pivot elenchi'!Q19=""),"",IF('Pivot elenchi'!Q18="",'Pivot elenchi'!Q17="",'Pivot elenchi'!Q18)) -> CONTABILITA' FORNITORI | N19: =IF(AND('Pivot elenchi'!R18="",'Pivot elenchi'!R19=""),"",IF('Pivot elenchi'!R18="",'Pivot elenchi'!R17="",'Pivot elenchi'!R18)) | O19: =IF(AND('Pivot elenchi'!S18="",'Pivot elenchi'!S19=""),"",IF('Pivot elenchi'!S18="",'Pivot elenchi'!S17="",'Pivot elenchi'!S18)) -> AMMINISTRAZIONE E BILANCIO | P19: =IF(AND('Pivot elenchi'!T18="",'Pivot elenchi'!T19=""),"",IF('Pivot elenchi'!T18="",'Pivot elenchi'!T17="",'Pivot elenchi'!T18)) | Q19: =IF(AND('Pivot elenchi'!U18="",'Pivot elenchi'!U19=""),"",IF('Pivot elenchi'!U18="",'Pivot elenchi'!U17="",'Pivot elenchi'!U18)) -> AMMINISTRAZIONE, FINANZA E CONTROLLO | R19: @ilsole24ore.com | T19: =IF('Pivot elenchi'!D16="","",'Pivot elenchi'!D16) | U19: =IF('Pivot elenchi'!C16="","",'Pivot elenchi'!C16) | W19: =IF(G19="","",G19) | X19: =IF(H19="","",H19) | Y19: =IF(I19="","",I19) | Z19: =IF(J19="","",J19) | AB19: =L19 -> 21520012 | AC19: =M19 -> CONTABILITA' FORNITORI | AD19: =N19 | AE19: =O19 -> AMMINISTRAZIONE E BILANCIO | AF19: =P19 | AG19: =Q19 -> AMMINISTRAZIONE, FINANZA E CONTROLLO
A20: NO | D20: =IF('Pivot elenchi'!D17="","",'Pivot elenchi'!D17) | E20: =IF('Pivot elenchi'!C17="","",'Pivot elenchi'!C17) | G20: Altra Sede | J20: np | L20: =IF(AND('Pivot elenchi'!P19="",'Pivot elenchi'!P20=""),"",IF('Pivot elenchi'!P19="",'Pivot elenchi'!P18="",'Pivot elenchi'!P19)) -> 21520013 | M20: =IF(AND('Pivot elenchi'!Q19="",'Pivot elenchi'!Q20=""),"",IF('Pivot elenchi'!Q19="",'Pivot elenchi'!Q18="",'Pivot elenchi'!Q19)) -> CONTABILITA' CLIENTI | N20: =IF(AND('Pivot elenchi'!R19="",'Pivot elenchi'!R20=""),"",IF('Pivot elenchi'!R19="",'Pivot elenchi'!R18="",'Pivot elenchi'!R19)) | O20: =IF(AND('Pivot elenchi'!S19="",'Pivot elenchi'!S20=""),"",IF('Pivot elenchi'!S19="",'Pivot elenchi'!S18="",'Pivot elenchi'!S19)) -> AMMINISTRAZIONE E BILANCIO | P20: =IF(AND('Pivot elenchi'!T19="",'Pivot elenchi'!T20=""),"",IF('Pivot elenchi'!T19="",'Pivot elenchi'!T18="",'Pivot elenchi'!T19)) | Q20: =IF(AND('Pivot elenchi'!U19="",'Pivot elenchi'!U20=""),"",IF('Pivot elenchi'!U19="",'Pivot elenchi'!U18="",'Pivot elenchi'!U19)) -> AMMINISTRAZIONE, FINANZA E CONTROLLO | R20: @ilsole24ore.com | W20: =IF(G20="","",G20) -> Altra Sede | X20: =IF(H20="","",H20) | Y20: =IF(I20="","",I20) | Z20: =IF(J20="","",J20) -> np | AB20: =L20 -> 21520013 | AC20: =M20 -> CONTABILITA' CLIENTI | AD20: =N20 | AE20: =O20 -> AMMINISTRAZIONE E BILANCIO | AF20: =P20 | AG20: =Q20 -> AMMINISTRAZIONE, FINANZA E CONTROLLO
D21: =IF('Pivot elenchi'!D18="","",'Pivot elenchi'!D18) | E21: =IF('Pivot elenchi'!C18="","",'Pivot elenchi'!C18) | G21: =IF('Pivot elenchi'!I18="","",'Pivot elenchi'!I18) | I21: =IF('Pivot elenchi'!J18="","",'Pivot elenchi'!J18) | J21: =IF('Pivot elenchi'!H18="","",'Pivot elenchi'!H18) | L21: =IF(AND('Pivot elenchi'!P20="",'Pivot elenchi'!P21=""),"",IF('Pivot elenchi'!P20="",'Pivot elenchi'!P19="",'Pivot elenchi'!P20)) -> 215500 | M21: =IF(AND('Pivot elenchi'!Q20="",'Pivot elenchi'!Q21=""),"",IF('Pivot elenchi'!Q20="",'Pivot elenchi'!Q19="",'Pivot elenchi'!Q20)) -> FINANZA, TESORERIA E RISK MAN | N21: =IF(AND('Pivot elenchi'!R20="",'Pivot elenchi'!R21=""),"",IF('Pivot elenchi'!R20="",'Pivot elenchi'!R19="",'Pivot elenchi'!R20)) | O21: =IF(AND('Pivot elenchi'!S20="",'Pivot elenchi'!S21=""),"",IF('Pivot elenchi'!S20="",'Pivot elenchi'!S19="",'Pivot elenchi'!S20)) -> FINANZA, TESORERIA E RISK MANAGEMENT | P21: =IF(AND('Pivot elenchi'!T20="",'Pivot elenchi'!T21=""),"",IF('Pivot elenchi'!T20="",'Pivot elenchi'!T19="",'Pivot elenchi'!T20)) | Q21: =IF(AND('Pivot elenchi'!U20="",'Pivot elenchi'!U21=""),"",IF('Pivot elenchi'!U20="",'Pivot elenchi'!U19="",'Pivot elenchi'!U20)) -> AMMINISTRAZIONE, FINANZA E CONTROLLO | R21: @ilsole24ore.com | W21: =IF(G21="","",G21) | X21: =IF(H21="","",H21) | Y21: =IF(I21="","",I21) | Z21: =IF(J21="","",J21) | AB21: =L21 -> 215500 | AC21: =M21 -> FINANZA, TESORERIA E RISK MAN | AD21: =N21 | AE21: =O21 -> FINANZA, TESORERIA E RISK MANAGEMENT | AF21: =P21 | AG21: =Q21 -> AMMINISTRAZIONE, FINANZA E CONTROLLO
G22: =IF('Pivot elenchi'!I19="","",'Pivot elenchi'!I19) | I22: =IF('Pivot elenchi'!J19="","",'Pivot elenchi'!J19) | J22: =IF('Pivot elenchi'!H19="","",'Pivot elenchi'!H19) | L22: =IF(AND('Pivot elenchi'!P21="",'Pivot elenchi'!P22=""),"",IF('Pivot elenchi'!P21="",'Pivot elenchi'!P20="",'Pivot elenchi'!P21)) -> 21550001 | M22: =IF(AND('Pivot elenchi'!Q21="",'Pivot elenchi'!Q22=""),"",IF('Pivot elenchi'!Q21="",'Pivot elenchi'!Q20="",'Pivot elenchi'!Q21)) -> TESORERIA E RISK MANAGEMENT | N22: =IF(AND('Pivot elenchi'!R21="",'Pivot elenchi'!R22=""),"",IF('Pivot elenchi'!R21="",'Pivot elenchi'!R20="",'Pivot elenchi'!R21)) | O22: =IF(AND('Pivot elenchi'!S21="",'Pivot elenchi'!S22=""),"",IF('Pivot elenchi'!S21="",'Pivot elenchi'!S20="",'Pivot elenchi'!S21)) -> FINANZA, TESORERIA E RISK MANAGEMENT | P22: =IF(AND('Pivot elenchi'!T21="",'Pivot elenchi'!T22=""),"",IF('Pivot elenchi'!T21="",'Pivot elenchi'!T20="",'Pivot elenchi'!T21)) | Q22: =IF(AND('Pivot elenchi'!U21="",'Pivot elenchi'!U22=""),"",IF('Pivot elenchi'!U21="",'Pivot elenchi'!U20="",'Pivot elenchi'!U21)) -> AMMINISTRAZIONE, FINANZA E CONTROLLO | R22: @ilsole24ore.com | W22: =IF(G22="","",G22) | X22: =IF(H22="","",H22) | Y22: =IF(I22="","",I22) | Z22: =IF(J22="","",J22) | AB22: =L22 -> 21550001 | AC22: =M22 -> TESORERIA E RISK MANAGEMENT | AD22: =N22 | AE22: =O22 -> FINANZA, TESORERIA E RISK MANAGEMENT | AF22: =P22 | AG22: =Q22 -> AMMINISTRAZIONE, FINANZA E CONTROLLO
A23: Telelavoro | G23: =IF('Pivot elenchi'!I20="","",'Pivot elenchi'!I20) | I23: =IF('Pivot elenchi'!J20="","",'Pivot elenchi'!J20) | J23: =IF('Pivot elenchi'!H20="","",'Pivot elenchi'!H20) | L23: =IF(AND('Pivot elenchi'!P22="",'Pivot elenchi'!P23=""),"",IF('Pivot elenchi'!P22="",'Pivot elenchi'!P21="",'Pivot elenchi'!P22)) -> 310000 | M23: =IF(AND('Pivot elenchi'!Q22="",'Pivot elenchi'!Q23=""),"",IF('Pivot elenchi'!Q22="",'Pivot elenchi'!Q21="",'Pivot elenchi'!Q22)) -> DIR. CENTR. PERSONALE E ORG. | N23: =IF(AND('Pivot elenchi'!R22="",'Pivot elenchi'!R23=""),"",IF('Pivot elenchi'!R22="",'Pivot elenchi'!R21="",'Pivot elenchi'!R22)) | O23: =IF(AND('Pivot elenchi'!S22="",'Pivot elenchi'!S23=""),"",IF('Pivot elenchi'!S22="",'Pivot elenchi'!S21="",'Pivot elenchi'!S22)) -> DIREZIONE PERSONALE | P23: =IF(AND('Pivot elenchi'!T22="",'Pivot elenchi'!T23=""),"",IF('Pivot elenchi'!T22="",'Pivot elenchi'!T21="",'Pivot elenchi'!T22)) | Q23: =IF(AND('Pivot elenchi'!U22="",'Pivot elenchi'!U23=""),"",IF('Pivot elenchi'!U22="",'Pivot elenchi'!U21="",'Pivot elenchi'!U22)) -> DIREZIONE CENTRALE PERSONALE E ORGANIZZA | R23: @ilsole24ore.com | W23: =IF(G23="","",G23) | X23: =IF(H23="","",H23) | Y23: =IF(I23="","",I23) | Z23: =IF(J23="","",J23) | AB23: =L23 -> 310000 | AC23: =M23 -> DIR. CENTR. PERSONALE E ORG. | AD23: =N23 | AE23: =O23 -> DIREZIONE PERSONALE | AF23: =P23 | AG23: =Q23 -> DIREZIONE CENTRALE PERSONALE E ORGANIZZA
A24: NO | G24: =IF('Pivot elenchi'!I21="","",'Pivot elenchi'!I21) | I24: =IF('Pivot elenchi'!J21="","",'Pivot elenchi'!J21) | J24: =IF('Pivot elenchi'!H21="","",'Pivot elenchi'!H21) | L24: =IF(AND('Pivot elenchi'!P23="",'Pivot elenchi'!P24=""),"",IF('Pivot elenchi'!P23="",'Pivot elenchi'!P22="",'Pivot elenchi'!P23)) -> 31000010 | M24: =IF(AND('Pivot elenchi'!Q23="",'Pivot elenchi'!Q24=""),"",IF('Pivot elenchi'!Q23="",'Pivot elenchi'!Q22="",'Pivot elenchi'!Q23)) -> GEST.PERSONALE DIR.FUNZ.CENTR. | N24: =IF(AND('Pivot elenchi'!R23="",'Pivot elenchi'!R24=""),"",IF('Pivot elenchi'!R23="",'Pivot elenchi'!R22="",'Pivot elenchi'!R23)) | O24: =IF(AND('Pivot elenchi'!S23="",'Pivot elenchi'!S24=""),"",IF('Pivot elenchi'!S23="",'Pivot elenchi'!S22="",'Pivot elenchi'!S23)) -> DIREZIONE PERSONALE | P24: =IF(AND('Pivot elenchi'!T23="",'Pivot elenchi'!T24=""),"",IF('Pivot elenchi'!T23="",'Pivot elenchi'!T22="",'Pivot elenchi'!T23)) | Q24: =IF(AND('Pivot elenchi'!U23="",'Pivot elenchi'!U24=""),"",IF('Pivot elenchi'!U23="",'Pivot elenchi'!U22="",'Pivot elenchi'!U23)) -> DIREZIONE CENTRALE PERSONALE E ORGANIZZA | R24: @ilsole24ore.com | W24: =IF(G26="","",G26) | X24: =IF(H26="","",H26) | Y24: =IF(I26="","",I26) | Z24: =IF(J26="","",J26) | AB24: =L24 -> 31000010 | AC24: =M24 -> GEST.PERSONALE DIR.FUNZ.CENTR. | AD24: =N24 | AE24: =O24 -> DIREZIONE PERSONALE | AF24: =P24 | AG24: =Q24 -> DIREZIONE CENTRALE PERSONALE E ORGANIZZA
A25: SI | L25: =IF(AND('Pivot elenchi'!P24="",'Pivot elenchi'!P25=""),"",IF('Pivot elenchi'!P24="",'Pivot elenchi'!P23="",'Pivot elenchi'!P24)) -> 31000020 | M25: =IF(AND('Pivot elenchi'!Q24="",'Pivot elenchi'!Q25=""),"",IF('Pivot elenchi'!Q24="",'Pivot elenchi'!Q23="",'Pivot elenchi'!Q24)) -> ORGANIZZAZIONE | N25: =IF(AND('Pivot elenchi'!R24="",'Pivot elenchi'!R25=""),"",IF('Pivot elenchi'!R24="",'Pivot elenchi'!R23="",'Pivot elenchi'!R24)) | O25: =IF(AND('Pivot elenchi'!S24="",'Pivot elenchi'!S25=""),"",IF('Pivot elenchi'!S24="",'Pivot elenchi'!S23="",'Pivot elenchi'!S24)) -> DIREZIONE PERSONALE | P25: =IF(AND('Pivot elenchi'!T24="",'Pivot elenchi'!T25=""),"",IF('Pivot elenchi'!T24="",'Pivot elenchi'!T23="",'Pivot elenchi'!T24)) | Q25: =IF(AND('Pivot elenchi'!U24="",'Pivot elenchi'!U25=""),"",IF('Pivot elenchi'!U24="",'Pivot elenchi'!U23="",'Pivot elenchi'!U24)) -> DIREZIONE CENTRALE PERSONALE E ORGANIZZA | R25: @ilsole24ore.com | W25: =IF(G27="","",G27) | X25: =IF(H27="","",H27) | Y25: =IF(I27="","",I27) | Z25: =IF(J27="","",J27) | AB25: =L25 -> 31000020 | AC25: =M25 -> ORGANIZZAZIONE | AD25: =N25 | AE25: =O25 -> DIREZIONE PERSONALE | AF25: =P25 | AG25: =Q25 -> DIREZIONE CENTRALE PERSONALE E ORGANIZZA
L26: =IF(AND('Pivot elenchi'!P25="",'Pivot elenchi'!P26=""),"",IF('Pivot elenchi'!P25="",'Pivot elenchi'!P24="",'Pivot elenchi'!P25)) -> 311000 | M26: =IF(AND('Pivot elenchi'!Q25="",'Pivot elenchi'!Q26=""),"",IF('Pivot elenchi'!Q25="",'Pivot elenchi'!Q24="",'Pivot elenchi'!Q25)) -> GEST.PERSONALE DIR.IT E BUSINES | N26: =IF(AND('Pivot elenchi'!R25="",'Pivot elenchi'!R26=""),"",IF('Pivot elenchi'!R25="",'Pivot elenchi'!R24="",'Pivot elenchi'!R25)) | O26: =IF(AND('Pivot elenchi'!S25="",'Pivot elenchi'!S26=""),"",IF('Pivot elenchi'!S25="",'Pivot elenchi'!S24="",'Pivot elenchi'!S25)) -> DIREZIONE PERSONALE | P26: =IF(AND('Pivot elenchi'!T25="",'Pivot elenchi'!T26=""),"",IF('Pivot elenchi'!T25="",'Pivot elenchi'!T24="",'Pivot elenchi'!T25)) | Q26: =IF(AND('Pivot elenchi'!U25="",'Pivot elenchi'!U26=""),"",IF('Pivot elenchi'!U25="",'Pivot elenchi'!U24="",'Pivot elenchi'!U25)) -> DIREZIONE CENTRALE PERSONALE E ORGANIZZA | R26: @ilsole24ore.com | W26: =IF(G28="","",G28) | X26: =IF(H28="","",H28) | Y26: =IF(I28="","",I28) | Z26: =IF(J28="","",J28) | AB26: =L26 -> 311000 | AC26: =M26 -> GEST.PERSONALE DIR.IT E BUSINES | AD26: =N26 | AE26: =O26 -> DIREZIONE PERSONALE | AF26: =P26 | AG26: =Q26 -> DIREZIONE CENTRALE PERSONALE E ORGANIZZA
A27: =IF('Scheda Movimento'!C9="","",'Scheda Movimento'!C9) -> Femminile | B27: =IF(A27="","",VLOOKUP(A27,A29:B32,2,FALSE)) -> F | L27: =IF(AND('Pivot elenchi'!P26="",'Pivot elenchi'!P27=""),"",IF('Pivot elenchi'!P26="",'Pivot elenchi'!P25="",'Pivot elenchi'!P26)) -> 312000 | M27: =IF(AND('Pivot elenchi'!Q26="",'Pivot elenchi'!Q27=""),"",IF('Pivot elenchi'!Q26="",'Pivot elenchi'!Q25="",'Pivot elenchi'!Q26)) -> NORME E AMMINISTR DEL PERSONALE | N27: =IF(AND('Pivot elenchi'!R26="",'Pivot elenchi'!R27=""),"",IF('Pivot elenchi'!R26="",'Pivot elenchi'!R25="",'Pivot elenchi'!R26)) | O27: =IF(AND('Pivot elenchi'!S26="",'Pivot elenchi'!S27=""),"",IF('Pivot elenchi'!S26="",'Pivot elenchi'!S25="",'Pivot elenchi'!S26)) -> DIREZIONE PERSONALE | P27: =IF(AND('Pivot elenchi'!T26="",'Pivot elenchi'!T27=""),"",IF('Pivot elenchi'!T26="",'Pivot elenchi'!T25="",'Pivot elenchi'!T26)) | Q27: =IF(AND('Pivot elenchi'!U26="",'Pivot elenchi'!U27=""),"",IF('Pivot elenchi'!U26="",'Pivot elenchi'!U25="",'Pivot elenchi'!U26)) -> DIREZIONE CENTRALE PERSONALE E ORGANIZZA | R27: @ilsole24ore.com | W27: =IF(G29="","",G29) | X27: =IF(H29="","",H29) | Y27: =IF(I29="","",I29) | Z27: =IF(J29="","",J29) | AB27: =L27 -> 312000 | AC27: =M27 -> NORME E AMMINISTR DEL PERSONALE | AD27: =N27 | AE27: =O27 -> DIREZIONE PERSONALE | AF27: =P27 | AG27: =Q27 -> DIREZIONE CENTRALE PERSONALE E ORGANIZZA
A28: Sesso | B28: COD | D28: Suffissi email | L28: =IF(AND('Pivot elenchi'!P27="",'Pivot elenchi'!P28=""),"",IF('Pivot elenchi'!P27="",'Pivot elenchi'!P26="",'Pivot elenchi'!P27)) -> 412620 | M28: =IF(AND('Pivot elenchi'!Q27="",'Pivot elenchi'!Q28=""),"",IF('Pivot elenchi'!Q27="",'Pivot elenchi'!Q26="",'Pivot elenchi'!Q27)) -> COORDINAMENTO TECNICO PRODUTTIV | N28: =IF(AND('Pivot elenchi'!R27="",'Pivot elenchi'!R28=""),"",IF('Pivot elenchi'!R27="",'Pivot elenchi'!R26="",'Pivot elenchi'!R27)) | O28: =IF(AND('Pivot elenchi'!S27="",'Pivot elenchi'!S28=""),"",IF('Pivot elenchi'!S27="",'Pivot elenchi'!S26="",'Pivot elenchi'!S27)) -> OPERATIONS DG P&D | P28: =IF(AND('Pivot elenchi'!T27="",'Pivot elenchi'!T28=""),"",IF('Pivot elenchi'!T27="",'Pivot elenchi'!T26="",'Pivot elenchi'!T27)) | Q28: =IF(AND('Pivot elenchi'!U27="",'Pivot elenchi'!U28=""),"",IF('Pivot elenchi'!U27="",'Pivot elenchi'!U26="",'Pivot elenchi'!U27)) -> DG M&B - DG PUBLISHING & DIGITAL | R28: @ilsole24ore.com | AB28: =L28 -> 412620 | AC28: =M28 -> COORDINAMENTO TECNICO PRODUTTIV | AD28: =N28 | AE28: =O28 -> OPERATIONS DG P&D | AF28: =P28 | AG28: =Q28 -> DG M&B - DG PUBLISHING & DIGITAL
L29: =IF(AND('Pivot elenchi'!P28="",'Pivot elenchi'!P29=""),"",IF('Pivot elenchi'!P28="",'Pivot elenchi'!P27="",'Pivot elenchi'!P28)) -> 412700 | M29: =IF(AND('Pivot elenchi'!Q28="",'Pivot elenchi'!Q29=""),"",IF('Pivot elenchi'!Q28="",'Pivot elenchi'!Q27="",'Pivot elenchi'!Q28)) -> PREP. EDITORIALE PROFESSIONALE | N29: =IF(AND('Pivot elenchi'!R28="",'Pivot elenchi'!R29=""),"",IF('Pivot elenchi'!R28="",'Pivot elenchi'!R27="",'Pivot elenchi'!R28)) | O29: =IF(AND('Pivot elenchi'!S28="",'Pivot elenchi'!S29=""),"",IF('Pivot elenchi'!S28="",'Pivot elenchi'!S27="",'Pivot elenchi'!S28)) -> OPERATIONS E CUSTOMER ENGAGEMENT | P29: =IF(AND('Pivot elenchi'!T28="",'Pivot elenchi'!T29=""),"",IF('Pivot elenchi'!T28="",'Pivot elenchi'!T27="",'Pivot elenchi'!T28)) | Q29: =IF(AND('Pivot elenchi'!U28="",'Pivot elenchi'!U29=""),"",IF('Pivot elenchi'!U28="",'Pivot elenchi'!U27="",'Pivot elenchi'!U28)) -> DG SERVIZI PROFESSIONALI E FORMAZIONE | R29: @ilsole24ore.com | AB29: =L29 -> 412700 | AC29: =M29 -> PREP. EDITORIALE PROFESSIONALE | AD29: =N29 | AE29: =O29 -> OPERATIONS E CUSTOMER ENGAGEMENT | AF29: =P29 | AG29: =Q29 -> DG SERVIZI PROFESSIONALI E FORMAZIONE
A30: Maschile | B30: M | D30: @ilsole24ore.com | L30: =IF(AND('Pivot elenchi'!P29="",'Pivot elenchi'!P30=""),"",IF('Pivot elenchi'!P29="",'Pivot elenchi'!P28="",'Pivot elenchi'!P29)) -> 413000 | M30: =IF(AND('Pivot elenchi'!Q29="",'Pivot elenchi'!Q30=""),"",IF('Pivot elenchi'!Q29="",'Pivot elenchi'!Q28="",'Pivot elenchi'!Q29)) -> ACQUISTI | N30: =IF(AND('Pivot elenchi'!R29="",'Pivot elenchi'!R30=""),"",IF('Pivot elenchi'!R29="",'Pivot elenchi'!R28="",'Pivot elenchi'!R29)) | O30: =IF(AND('Pivot elenchi'!S29="",'Pivot elenchi'!S30=""),"",IF('Pivot elenchi'!S29="",'Pivot elenchi'!S28="",'Pivot elenchi'!S29)) -> ACQUISTI | P30: =IF(AND('Pivot elenchi'!T29="",'Pivot elenchi'!T30=""),"",IF('Pivot elenchi'!T29="",'Pivot elenchi'!T28="",'Pivot elenchi'!T29)) | Q30: =IF(AND('Pivot elenchi'!U29="",'Pivot elenchi'!U30=""),"",IF('Pivot elenchi'!U29="",'Pivot elenchi'!U28="",'Pivot elenchi'!U29)) -> DIREZIONE CENTRALE PERSONALE E ORGANIZZA | R30: @ilsole24ore.com | AB30: =L30 -> 413000 | AC30: =M30 -> ACQUISTI | AD30: =N30 | AE30: =O30 -> ACQUISTI | AF30: =P30 | AG30: =Q30 -> DIREZIONE CENTRALE PERSONALE E ORGANIZZA
A31: Femminile | B31: F | D31: @24orecultura.com | L31: =IF(AND('Pivot elenchi'!P30="",'Pivot elenchi'!P31=""),"",IF('Pivot elenchi'!P30="",'Pivot elenchi'!P29="",'Pivot elenchi'!P30)) -> 414000 | M31: =IF(AND('Pivot elenchi'!Q30="",'Pivot elenchi'!Q31=""),"",IF('Pivot elenchi'!Q30="",'Pivot elenchi'!Q29="",'Pivot elenchi'!Q30)) -> SERVIZI GENERALI SICUREZZA E AM | N31: =IF(AND('Pivot elenchi'!R30="",'Pivot elenchi'!R31=""),"",IF('Pivot elenchi'!R30="",'Pivot elenchi'!R29="",'Pivot elenchi'!R30)) | O31: =IF(AND('Pivot elenchi'!S30="",'Pivot elenchi'!S31=""),"",IF('Pivot elenchi'!S30="",'Pivot elenchi'!S29="",'Pivot elenchi'!S30)) -> SERVIZI GENERALI SICUREZZA E AMBIENTE | P31: =IF(AND('Pivot elenchi'!T30="",'Pivot elenchi'!T31=""),"",IF('Pivot elenchi'!T30="",'Pivot elenchi'!T29="",'Pivot elenchi'!T30)) | Q31: =IF(AND('Pivot elenchi'!U30="",'Pivot elenchi'!U31=""),"",IF('Pivot elenchi'!U30="",'Pivot elenchi'!U29="",'Pivot elenchi'!U30)) -> DIREZIONE CENTRALE PERSONALE E ORGANIZZA | R31: @ilsole24ore.com | AB31: =L31 -> 414000 | AC31: =M31 -> SERVIZI GENERALI SICUREZZA E AM | AD31: =N31 | AE31: =O31 -> SERVIZI GENERALI SICUREZZA E AMBIENTE | AF31: =P31 | AG31: =Q31 -> DIREZIONE CENTRALE PERSONALE E ORGANIZZA
D32: @radio24.it | L32: =IF(AND('Pivot elenchi'!P31="",'Pivot elenchi'!P32=""),"",IF('Pivot elenchi'!P31="",'Pivot elenchi'!P30="",'Pivot elenchi'!P31)) -> 41400001 | M32: =IF(AND('Pivot elenchi'!Q31="",'Pivot elenchi'!Q32=""),"",IF('Pivot elenchi'!Q31="",'Pivot elenchi'!Q30="",'Pivot elenchi'!Q31)) -> SUPPORTO TECNICO E HSE | N32: =IF(AND('Pivot elenchi'!R31="",'Pivot elenchi'!R32=""),"",IF('Pivot elenchi'!R31="",'Pivot elenchi'!R30="",'Pivot elenchi'!R31)) | O32: =IF(AND('Pivot elenchi'!S31="",'Pivot elenchi'!S32=""),"",IF('Pivot elenchi'!S31="",'Pivot elenchi'!S30="",'Pivot elenchi'!S31)) -> SERVIZI GENERALI SICUREZZA E AMBIENTE | P32: =IF(AND('Pivot elenchi'!T31="",'Pivot elenchi'!T32=""),"",IF('Pivot elenchi'!T31="",'Pivot elenchi'!T30="",'Pivot elenchi'!T31)) | Q32: =IF(AND('Pivot elenchi'!U31="",'Pivot elenchi'!U32=""),"",IF('Pivot elenchi'!U31="",'Pivot elenchi'!U30="",'Pivot elenchi'!U31)) -> DIREZIONE CENTRALE PERSONALE E ORGANIZZA | R32: @ilsole24ore.com | AB32: =L32 -> 41400001 | AC32: =M32 -> SUPPORTO TECNICO E HSE | AD32: =N32 | AE32: =O32 -> SERVIZI GENERALI SICUREZZA E AMBIENTE | AF32: =P32 | AG32: =Q32 -> DIREZIONE CENTRALE PERSONALE E ORGANIZZA
L33: =IF(AND('Pivot elenchi'!P32="",'Pivot elenchi'!P33=""),"",IF('Pivot elenchi'!P32="",'Pivot elenchi'!P31="",'Pivot elenchi'!P32)) -> 414100 | M33: =IF(AND('Pivot elenchi'!Q32="",'Pivot elenchi'!Q33=""),"",IF('Pivot elenchi'!Q32="",'Pivot elenchi'!Q31="",'Pivot elenchi'!Q32)) -> COORDINAMENTO OPERATIVO | N33: =IF(AND('Pivot elenchi'!R32="",'Pivot elenchi'!R33=""),"",IF('Pivot elenchi'!R32="",'Pivot elenchi'!R31="",'Pivot elenchi'!R32)) | O33: =IF(AND('Pivot elenchi'!S32="",'Pivot elenchi'!S33=""),"",IF('Pivot elenchi'!S32="",'Pivot elenchi'!S31="",'Pivot elenchi'!S32)) -> SERVIZI GENERALI SICUREZZA E AMBIENTE | P33: =IF(AND('Pivot elenchi'!T32="",'Pivot elenchi'!T33=""),"",IF('Pivot elenchi'!T32="",'Pivot elenchi'!T31="",'Pivot elenchi'!T32)) | Q33: =IF(AND('Pivot elenchi'!U32="",'Pivot elenchi'!U33=""),"",IF('Pivot elenchi'!U32="",'Pivot elenchi'!U31="",'Pivot elenchi'!U32)) -> DIREZIONE CENTRALE PERSONALE E ORGANIZZA | R33: @ilsole24ore.com | AB33: =L33 -> 414100 | AC33: =M33 -> COORDINAMENTO OPERATIVO | AD33: =N33 | AE33: =O33 -> SERVIZI GENERALI SICUREZZA E AMBIENTE | AF33: =P33 | AG33: =Q33 -> DIREZIONE CENTRALE PERSONALE E ORGANIZZA
A34: =IF('Scheda Movimento'!C21="","",'Scheda Movimento'!C21) -> Contratto a tempo indeterminato | B34: =IF(A34="","",VLOOKUP(A34,A36:B52,2,FALSE)) -> 02 | L34: =IF(AND('Pivot elenchi'!P33="",'Pivot elenchi'!P34=""),"",IF('Pivot elenchi'!P33="",'Pivot elenchi'!P32="",'Pivot elenchi'!P33)) -> 415110 | M34: =IF(AND('Pivot elenchi'!Q33="",'Pivot elenchi'!Q34=""),"",IF('Pivot elenchi'!Q33="",'Pivot elenchi'!Q32="",'Pivot elenchi'!Q33)) -> SISTEMI INFORMATICI GESTIONALI | N34: =IF(AND('Pivot elenchi'!R33="",'Pivot elenchi'!R34=""),"",IF('Pivot elenchi'!R33="",'Pivot elenchi'!R32="",'Pivot elenchi'!R33)) | O34: =IF(AND('Pivot elenchi'!S33="",'Pivot elenchi'!S34=""),"",IF('Pivot elenchi'!S33="",'Pivot elenchi'!S32="",'Pivot elenchi'!S33)) -> SISTEMI INFORMATICI GESTIONALI | P34: =IF(AND('Pivot elenchi'!T33="",'Pivot elenchi'!T34=""),"",IF('Pivot elenchi'!T33="",'Pivot elenchi'!T32="",'Pivot elenchi'!T33)) | Q34: =IF(AND('Pivot elenchi'!U33="",'Pivot elenchi'!U34=""),"",IF('Pivot elenchi'!U33="",'Pivot elenchi'!U32="",'Pivot elenchi'!U33)) -> DG I&S - DIR INFORMATION TECHNOLOGY | R34: @ilsole24ore.com | AB34: =L34 -> 415110 | AC34: =M34 -> SISTEMI INFORMATICI GESTIONALI | AD34: =N34 | AE34: =O34 -> SISTEMI INFORMATICI GESTIONALI | AF34: =P34 | AG34: =Q34 -> DG I&S - DIR INFORMATION TECHNOLOGY
A35: CONTRATTO | B35: COD | L35: =IF(AND('Pivot elenchi'!P34="",'Pivot elenchi'!P35=""),"",IF('Pivot elenchi'!P34="",'Pivot elenchi'!P33="",'Pivot elenchi'!P34)) -> 415120 | M35: =IF(AND('Pivot elenchi'!Q34="",'Pivot elenchi'!Q35=""),"",IF('Pivot elenchi'!Q34="",'Pivot elenchi'!Q33="",'Pivot elenchi'!Q34)) -> INFRASTRUTTURE E IT NETWORKING | N35: =IF(AND('Pivot elenchi'!R34="",'Pivot elenchi'!R35=""),"",IF('Pivot elenchi'!R34="",'Pivot elenchi'!R33="",'Pivot elenchi'!R34)) | O35: =IF(AND('Pivot elenchi'!S34="",'Pivot elenchi'!S35=""),"",IF('Pivot elenchi'!S34="",'Pivot elenchi'!S33="",'Pivot elenchi'!S34)) -> INFRAST, IT NETWORK. E AREA TECN RADIO24 | P35: =IF(AND('Pivot elenchi'!T34="",'Pivot elenchi'!T35=""),"",IF('Pivot elenchi'!T34="",'Pivot elenchi'!T33="",'Pivot elenchi'!T34)) | Q35: =IF(AND('Pivot elenchi'!U34="",'Pivot elenchi'!U35=""),"",IF('Pivot elenchi'!U34="",'Pivot elenchi'!U33="",'Pivot elenchi'!U34)) -> DG I&S - DIR INFORMATION TECHNOLOGY | R35: @ilsole24ore.com | AB35: =L35 -> 415120 | AC35: =M35 -> INFRASTRUTTURE E IT NETWORKING | AD35: =N35 | AE35: =O35 -> INFRAST, IT NETWORK. E AREA TECN RADIO24 | AF35: =P35 | AG35: =Q35 -> DG I&S - DIR INFORMATION TECHNOLOGY
